<mujoco model="so101_PathonAI_6dof_symmetric_gripper">
  <compiler angle="radian" meshdir="meshes/"/>

  <default>
    <default class="robot">
      <default class="visual">
        <geom contype="0" conaffinity="0" group="2" material="gold"/>
      </default>
      <default class="collision">
        <geom contype="0" group="1" priority="1" friction="1 0.01 0.01" solref="0.005" solimp="0.99 0.999 1e-05" material="collision_material"/>
      </default>
    </default>
    <default class="sts3215">
      <joint armature="0.028" damping="0.6" frictionloss="0.052"/>
      <general biastype="affine" gainprm="17.8" biasprm="0 -17.8"/>
    </default>
    <default class="gripper_symmetric">
      <joint damping="1.0" frictionloss="0.1"/>
      <general biastype="affine" gainprm="50" biasprm="0 -50"/>
    </default>
  </default>

  <asset>
    <material name="gold" rgba="1 0.82 0.12 1"/>
    <material name="default_material" rgba="1 0.82 0.12 1"/>
    <material name="collision_material" rgba="1 0.28 0.1 0.9"/>
    <material name="gripper_material" rgba="0.95 0.75 0.1 1"/>
    <mesh name="base_link" content_type="model/stl" file="base_link.stl" scale="0.001 0.001 0.001"/>
    <mesh name="shoulder_link_1" content_type="model/stl" file="shoulder_link_1.stl" scale="0.001 0.001 0.001"/>
    <mesh name="upper_arm_link_1" content_type="model/stl" file="upper_arm_link_1.stl" scale="0.001 0.001 0.001"/>
    <mesh name="lower_arm_link_1" content_type="model/stl" file="lower_arm_link_1.stl" scale="0.001 0.001 0.001"/>
    <mesh name="link_pitch_1" content_type="model/stl" file="link_pitch_1.stl" scale="0.001 0.001 0.001"/>
    <mesh name="link_yaw_v1_1" content_type="model/stl" file="link_yaw_v1_1.stl" scale="0.001 0.001 0.001"/>
    <mesh name="link_roll_v1_1" content_type="model/stl" file="link_roll_v1_1.stl" scale="0.001 0.001 0.001"/>
    <mesh name="left_jaw_v1_1" content_type="model/stl" file="left_jaw_v1_1.stl" scale="0.001 0.001 0.001"/>
    <mesh name="right_jaw_v1_1" content_type="model/stl" file="right_jaw_v1_1.stl" scale="0.001 0.001 0.001"/>
  </asset>

  <worldbody>
    <body name="base_link" childclass="robot">
      <geom name="base_link_collision" class="collision" type="mesh" mesh="base_link"/>
      <geom name="base_link_visual" class="visual" type="mesh" mesh="base_link"/>
      <site name="base_link_site" pos="0 0 0"/>
      <camera name="front_camera" pos="0 2 0.5" quat="0 0 0.707107 0.707107" mode="track" fovy="90"/>
      <camera name="side_camera" pos="-2 0 0.5" quat="-0.5 -0.5 0.5 0.5" mode="track" fovy="90"/>
      <body name="shoulder_link" pos="0.025192 0.000209 0.066415">
        <inertial pos="0.0312503 -0.000258146 0.00842022" quat="0.680023 0.0239922 0.0148045 0.732649" mass="0.123404" diaginertia="0.000125015 0.000124273 3.37122e-05"/>
        <joint name="Revolute_1" class="sts3215" pos="0 0 0" axis="0.008727 0 0.999962" range="-2.06 2.01"/>
        <geom name="shoulder_link_collision" class="collision" pos="-0.025192 -0.000209 -0.066415" quat="1 0 0 0" type="mesh" mesh="shoulder_link_1"/>
        <geom name="shoulder_link_visual" class="visual" pos="-0.025192 -0.000209 -0.066415" quat="1 0 0 0" type="mesh" mesh="shoulder_link_1"/>
        <site name="Revolute_1_site" pos="0 0 0"/>
        <body name="upper_arm_link" pos="0.031308 -0.019759 0.051976">
          <inertial pos="0.00363689 0.0197508 0.072242" quat="0.998472 0.00273851 0.0551582 -0.00174794" mass="0.160514" diaginertia="0.000278549 0.000244005 6.84456e-05"/>
          <joint name="Revolute_2" class="sts3215" pos="0 0 0" axis="-0.008726 0.999962 7.6e-05" range="-1.75 1.75"/>
          <geom name="upper_arm_link_collision" class="collision" pos="-0.0565 0.01955 -0.118391" type="mesh" mesh="upper_arm_link_1"/>
          <geom name="upper_arm_link_visual" class="visual" pos="-0.0565 0.01955 -0.118391" type="mesh" mesh="upper_arm_link_1"/>
          <site name="Revolute_2_site" pos="0 0 0"/>
          <body name="lower_arm_link" pos="0.028677 0.001197 0.112459">
            <inertial pos="0.0768209 0.0194494 0.000785535" quat="-0.00315238 0.695506 0.00462283 0.718499" mass="0.149314" diaginertia="0.000268228 0.000234022 5.27503e-05"/>
            <joint name="Revolute_3" class="sts3215" pos="0 0 0" axis="0 -1 0" range="-1.52 1.76"/>
            <geom name="lower_arm_link_collision" class="collision" pos="-0.085177 0.018353 -0.23085" quat="1 0 0 0" type="mesh" mesh="lower_arm_link_1"/>
            <geom name="lower_arm_link_visual" class="visual" pos="-0.085177 0.018353 -0.23085" quat="1 0 0 0" type="mesh" mesh="lower_arm_link_1"/>
            <site name="Revolute_3_site" pos="0 0 0"/>
            <body name="wrist_pitch_link" pos="0.134099 0.000648 0.003829">
              <inertial pos="0.012444 0.0197006 0.00705533" quat="0.680193 0.680193 0.193229 -0.193229" mass="0.0177225" diaginertia="8.61803e-06 6.38197e-06 6e-06"/>
              <joint name="Revolute_4" class="sts3215" pos="0 0 0" axis="-0.008802 -0.999924 -0.00865" range="-1.69 1.38"/>
              <geom name="wrist_pitch_link_collision" class="collision" pos="-0.219276 0.017705 -0.234679" type="mesh" mesh="link_pitch_1"/>
              <geom name="wrist_pitch_link_visual" class="visual" pos="-0.219276 0.017705 -0.234679" type="mesh" mesh="link_pitch_1"/>
              <site name="Revolute_4_site" pos="0 0 0"/>
              <body name="wrist_yaw_link" pos="0.029296 0.019056 0.036617">
                <inertial pos="0.0244999 -4.29874e-05 -0.0041547" quat="0.693 -0.140536 -0.140536 0.693" mass="0.0856768" diaginertia="7.5e-05 6.61907e-05 1.88093e-05"/>
                <joint name="Revolute_5" class="sts3215" pos="0 0 0" axis="0.014193 -5e-05 0.999899" range="-1.40 1.32"/>
                <geom name="wrist_yaw_link_collision" class="collision" pos="-0.248572 -0.001351 -0.271296" quat="1 0 0 0" type="mesh" mesh="link_yaw_v1_1"/>
                <geom name="wrist_yaw_link_visual" class="visual" pos="-0.248572 -0.001351 -0.271296" quat="1 0 0 0" type="mesh" mesh="link_yaw_v1_1"/>
                <site name="Revolute_5_site" pos="0 0 0"/>
                <body name="wrist_roll_link" pos="0.055567 -0.000176 -0.037221">
                  <inertial pos="0.0297692 -0.000340441 0.00753887" quat="0.951641 0 -0.307212 0" mass="0.0659461" diaginertia="3.11623e-05 2.7e-05 2.48377e-05"/>
                  <joint name="Revolute_6" class="sts3215" pos="0 0 0" axis="0.999922 -0.008805 -0.008802" range="-3.08 3.09"/>
                  <geom name="wrist_roll_link_collision" class="collision" pos="-0.304139 -0.001175 -0.234075" quat="1 0 0 0" type="mesh" mesh="link_roll_v1_1"/>
                  <geom name="wrist_roll_link_visual" class="visual" pos="-0.304139 -0.001175 -0.234075" quat="1 0 0 0" type="mesh" mesh="link_roll_v1_1"/>
                  <site name="Revolute_6_site" pos="0 0 0" rgba="0 0 1 1"/>
                  <site name="attachment_site" pos="0 0 0" quat="0.5 -0.5 -0.5 0.5" size="0.01" rgba="1 0 0 1"/>
                  <body name="left_jaw" pos="0.04361 0.021616 0.020519" childclass="gripper_symmetric">
                    <inertial pos="0.0238065 -0.00169967 -0.0194467" quat="0.392847 0.587938 0.587938 0.392847" mass="0.0166241" diaginertia="8e-06 6.41421e-06 3.58579e-06"/>
                    <joint name="left_jaw_slider" pos="0 0 0" axis="0.008881 0.999923 0.008649" type="slide" limited="true" range="-0.013 0.013"/>
                    <geom name="left_jaw_collision" class="collision" pos="-0.347749 -0.040991 -0.254594" quat="1 0 0 0" type="mesh" mesh="left_jaw_v1_1"/>
                    <geom name="left_jaw_visual" class="visual" pos="-0.347749 -0.040991 -0.254594" quat="1 0 0 0" type="mesh" mesh="left_jaw_v1_1" material="gripper_material"/>
                    <site name="left_jaw_tip" pos="0.03 0 0"/>
                  </body>
                  <body name="right_jaw" pos="0.043251 -0.022781 0.02017" childclass="gripper_symmetric">
                    <inertial pos="0.0238082 0.00164092 -0.0226258" quat="0.5 0.5 0.5 0.5" mass="0.016624" diaginertia="8e-06 6e-06 4e-06"/>
                    <joint name="right_jaw_slider" pos="0 0 0" axis="0.008881 0.999923 0.008649" type="slide" limited="true" range="-0.013 0.013"/>
                    <geom name="right_jaw_collision" class="collision" pos="-0.34739 -0.000594 -0.254245" quat="1 0 0 0" type="mesh" mesh="right_jaw_v1_1"/>
                    <geom name="right_jaw_visual" class="visual" pos="-0.34739 -0.000594 -0.254245" quat="1 0 0 0" type="mesh" mesh="right_jaw_v1_1" material="gripper_material"/>
                    <site name="right_jaw_tip" pos="0.03 0 0"/>
                  </body>
                </body>
              </body>
            </body>
          </body>
        </body>
      </body>
    </body>
  </worldbody>

  <contact>
    <exclude body1="base_link" body2="shoulder_link"/>
    <exclude body1="shoulder_link" body2="upper_arm_link"/>
    <exclude body1="upper_arm_link" body2="lower_arm_link"/>
    <exclude body1="lower_arm_link" body2="wrist_pitch_link"/>
    <exclude body1="wrist_pitch_link" body2="wrist_yaw_link"/>
    <exclude body1="wrist_yaw_link" body2="wrist_roll_link"/>
  </contact>

  <equality>
    <joint joint1="left_jaw_slider" joint2="right_jaw_slider" polycoef="0 -1 0 0 0" solref="0.0002 1" solimp="0.999 0.9999 0.0001"/>
  </equality>

  <actuator>
    <general name="shoulder_pan" class="sts3215" joint="Revolute_1" ctrlrange="-2.06 2.01" forcerange="-3.35 3.35"/>
    <general name="shoulder_lift" class="sts3215" joint="Revolute_2" ctrlrange="-1.75 1.75" forcerange="-3.35 3.35"/>
    <general name="elbow_flex" class="sts3215" joint="Revolute_3" ctrlrange="-1.52 1.76" forcerange="-3.35 3.35"/>
    <general name="wrist_flex" class="sts3215" joint="Revolute_4" ctrlrange="-1.69 1.38" forcerange="-3.35 3.35"/>
    <general name="wrist_yaw" class="sts3215" joint="Revolute_5" ctrlrange="-1.40 1.32" forcerange="-3.35 3.35"/>
    <general name="wrist_roll" class="sts3215" joint="Revolute_6" ctrlrange="-3.08 3.09" forcerange="-3.35 3.35"/>
    <general name="gripper_jaw_motor" class="gripper_symmetric" joint="left_jaw_slider" ctrlrange="-0.013 0.013" forcerange="-5 5"/>
  </actuator>

  <keyframe>
    <key name="home" qpos="0 0 0 0 0 0 0 0"/>
  </keyframe>

  <sensor>
    <framepos objtype="site" objname="Revolute_1_site" name="Revolute_1_site_pos"/>
    <framequat objtype="site" objname="Revolute_1_site" name="Revolute_1_site_quat"/>
    <framelinvel objtype="site" objname="Revolute_1_site" name="Revolute_1_site_linvel"/>
    <frameangvel objtype="site" objname="Revolute_1_site" name="Revolute_1_site_angvel"/>
    <velocimeter site="Revolute_1_site" name="Revolute_1_site_vel"/>
  </sensor>
</mujoco>
