<?xml version="1.0" ?>
<!-- =================================================================================== -->
<!-- |    This document was autogenerated by xacro from /home/pathonai/urdf_ws/src/so101_PathonAI_6dof_symmetric_gripper_description/urdf/so101_PathonAI_6dof_symmetric_gripper.xacro | -->
<!-- |    EDITING THIS FILE BY HAND IS NOT RECOMMENDED                                 | -->
<!-- =================================================================================== -->
<robot name="so101_PathonAI_6dof_symmetric_gripper">
  <material name="silver">
    <color rgba="0.700 0.700 0.700 1.000"/>
  </material>
  <transmission name="Revolute_1_tran">
    <type>transmission_interface/SimpleTransmission</type>
    <joint name="Revolute_1">
      <hardwareInterface>hardware_interface/EffortJointInterface</hardwareInterface>
    </joint>
    <actuator name="Revolute_1_actr">
      <hardwareInterface>hardware_interface/EffortJointInterface</hardwareInterface>
      <mechanicalReduction>1</mechanicalReduction>
    </actuator>
  </transmission>
  <transmission name="Revolute_2_tran">
    <type>transmission_interface/SimpleTransmission</type>
    <joint name="Revolute_2">
      <hardwareInterface>hardware_interface/EffortJointInterface</hardwareInterface>
    </joint>
    <actuator name="Revolute_2_actr">
      <hardwareInterface>hardware_interface/EffortJointInterface</hardwareInterface>
      <mechanicalReduction>1</mechanicalReduction>
    </actuator>
  </transmission>
  <transmission name="Revolute_3_tran">
    <type>transmission_interface/SimpleTransmission</type>
    <joint name="Revolute_3">
      <hardwareInterface>hardware_interface/EffortJointInterface</hardwareInterface>
    </joint>
    <actuator name="Revolute_3_actr">
      <hardwareInterface>hardware_interface/EffortJointInterface</hardwareInterface>
      <mechanicalReduction>1</mechanicalReduction>
    </actuator>
  </transmission>
  <transmission name="Revolute_4_tran">
    <type>transmission_interface/SimpleTransmission</type>
    <joint name="Revolute_4">
      <hardwareInterface>hardware_interface/EffortJointInterface</hardwareInterface>
    </joint>
    <actuator name="Revolute_4_actr">
      <hardwareInterface>hardware_interface/EffortJointInterface</hardwareInterface>
      <mechanicalReduction>1</mechanicalReduction>
    </actuator>
  </transmission>
  <transmission name="Revolute_5_tran">
    <type>transmission_interface/SimpleTransmission</type>
    <joint name="Revolute_5">
      <hardwareInterface>hardware_interface/EffortJointInterface</hardwareInterface>
    </joint>
    <actuator name="Revolute_5_actr">
      <hardwareInterface>hardware_interface/EffortJointInterface</hardwareInterface>
      <mechanicalReduction>1</mechanicalReduction>
    </actuator>
  </transmission>
  <transmission name="Revolute_6_tran">
    <type>transmission_interface/SimpleTransmission</type>
    <joint name="Revolute_6">
      <hardwareInterface>hardware_interface/EffortJointInterface</hardwareInterface>
    </joint>
    <actuator name="Revolute_6_actr">
      <hardwareInterface>hardware_interface/EffortJointInterface</hardwareInterface>
      <mechanicalReduction>1</mechanicalReduction>
    </actuator>
  </transmission>
  <transmission name="left_jaw_slider_tran">
    <type>transmission_interface/SimpleTransmission</type>
    <joint name="left_jaw_slider">
      <hardwareInterface>hardware_interface/EffortJointInterface</hardwareInterface>
    </joint>
    <actuator name="left_jaw_slider_actr">
      <hardwareInterface>hardware_interface/EffortJointInterface</hardwareInterface>
      <mechanicalReduction>1</mechanicalReduction>
    </actuator>
  </transmission>
  <transmission name="right_jaw_slider_tran">
    <type>transmission_interface/SimpleTransmission</type>
    <joint name="right_jaw_slider">
      <hardwareInterface>hardware_interface/EffortJointInterface</hardwareInterface>
    </joint>
    <actuator name="right_jaw_slider_actr">
      <hardwareInterface>hardware_interface/EffortJointInterface</hardwareInterface>
      <mechanicalReduction>1</mechanicalReduction>
    </actuator>
  </transmission>
  <gazebo>
    <plugin filename="libgazebo_ros_control.so" name="control"/>
  </gazebo>
  <gazebo reference="base_link">
    <material>Gazebo/Silver</material>
    <mu1>0.2</mu1>
    <mu2>0.2</mu2>
    <self_collide>true</self_collide>
    <gravity>true</gravity>
  </gazebo>
  <gazebo reference="link_yaw_v1_1">
    <material>Gazebo/Silver</material>
    <mu1>0.2</mu1>
    <mu2>0.2</mu2>
    <self_collide>true</self_collide>
  </gazebo>
  <gazebo reference="link_roll_v1_1">
    <material>Gazebo/Silver</material>
    <mu1>0.2</mu1>
    <mu2>0.2</mu2>
    <self_collide>true</self_collide>
  </gazebo>
  <gazebo reference="link_pitch_1">
    <material>Gazebo/Silver</material>
    <mu1>0.2</mu1>
    <mu2>0.2</mu2>
    <self_collide>true</self_collide>
  </gazebo>
  <gazebo reference="lower_arm_link_1">
    <material>Gazebo/Silver</material>
    <mu1>0.2</mu1>
    <mu2>0.2</mu2>
    <self_collide>true</self_collide>
  </gazebo>
  <gazebo reference="shoulder_link_1">
    <material>Gazebo/Silver</material>
    <mu1>0.2</mu1>
    <mu2>0.2</mu2>
    <self_collide>true</self_collide>
  </gazebo>
  <gazebo reference="upper_arm_link_1">
    <material>Gazebo/Silver</material>
    <mu1>0.2</mu1>
    <mu2>0.2</mu2>
    <self_collide>true</self_collide>
  </gazebo>
  <gazebo reference="left_jaw_v1_1">
    <material>Gazebo/Silver</material>
    <mu1>0.2</mu1>
    <mu2>0.2</mu2>
    <self_collide>true</self_collide>
  </gazebo>
  <gazebo reference="right_jaw_v1_1">
    <material>Gazebo/Silver</material>
    <mu1>0.2</mu1>
    <mu2>0.2</mu2>
    <self_collide>true</self_collide>
  </gazebo>
  <link name="base_link">
    <inertial>
      <origin rpy="0 0 0" xyz="-0.002181917231912958 0.0002385029900090826 0.030231283959863367"/>
      <mass value="0.19146543803266067"/>
      <inertia ixx="0.00019" ixy="-1e-06" ixz="1.3e-05" iyy="0.000188" iyz="0.0" izz="0.000196"/>
    </inertial>
    <visual>
      <origin rpy="0 0 0" xyz="0 0 0"/>
      <geometry>
        <mesh filename="meshes/base_link.stl" scale="0.001 0.001 0.001"/>
      </geometry>
      <material name="silver"/>
    </visual>
    <collision>
      <origin rpy="0 0 0" xyz="0 0 0"/>
      <geometry>
        <mesh filename="meshes/base_link.stl" scale="0.001 0.001 0.001"/>
      </geometry>
    </collision>
  </link>
  <link name="wrist_yaw_link">
    <inertial>
      <origin rpy="0 0 0" xyz="0.024499928462552473 -4.2987369628577935e-05 -0.004154699539631657"/>
      <mass value="0.08567679182758908"/>
      <inertia ixx="5.9e-05" ixy="0.0" ixz="1.7e-05" iyy="7.5e-05" iyz="0.0" izz="2.6e-05"/>
    </inertial>
    <visual>
      <origin rpy="0 0 0" xyz="-0.248572 -0.001351 -0.271296"/>
      <geometry>
        <mesh filename="meshes/link_yaw_v1_1.stl" scale="0.001 0.001 0.001"/>
      </geometry>
      <material name="silver"/>
    </visual>
    <collision>
      <origin rpy="0 0 0" xyz="-0.248572 -0.001351 -0.271296"/>
      <geometry>
        <mesh filename="meshes/link_yaw_v1_1.stl" scale="0.001 0.001 0.001"/>
      </geometry>
    </collision>
  </link>
  <link name="wrist_roll_link">
    <inertial>
      <origin rpy="0 0 0" xyz="0.029769169194226286 -0.0003404414774720009 0.007538866703660052"/>
      <mass value="0.06594606839949692"/>
      <inertia ixx="2.9e-05" ixy="-0.0" ixz="3e-06" iyy="2.7e-05" iyz="-0.0" izz="2.7e-05"/>
    </inertial>
    <visual>
      <origin rpy="0 0 0" xyz="-0.304139 -0.001175 -0.234075"/>
      <geometry>
        <mesh filename="meshes/link_roll_v1_1.stl" scale="0.001 0.001 0.001"/>
      </geometry>
      <material name="silver"/>
    </visual>
    <collision>
      <origin rpy="0 0 0" xyz="-0.304139 -0.001175 -0.234075"/>
      <geometry>
        <mesh filename="meshes/link_roll_v1_1.stl" scale="0.001 0.001 0.001"/>
      </geometry>
    </collision>
  </link>
  <link name="wrist_pitch_link">
    <inertial>
      <origin rpy="0 0 0" xyz="0.012444012165968216 0.019700647706552527 0.007055327401834982"/>
      <mass value="0.01772245044549146"/>
      <inertia ixx="8e-06" ixy="-0.0" ixz="-1e-06" iyy="6e-06" iyz="0.0" izz="7e-06"/>
    </inertial>
    <visual>
      <origin rpy="0 0 0" xyz="-0.219276 0.017705 -0.234679"/>
      <geometry>
        <mesh filename="meshes/link_pitch_1.stl" scale="0.001 0.001 0.001"/>
      </geometry>
      <material name="silver"/>
    </visual>
    <collision>
      <origin rpy="0 0 0" xyz="-0.219276 0.017705 -0.234679"/>
      <geometry>
        <mesh filename="meshes/link_pitch_1.stl" scale="0.001 0.001 0.001"/>
      </geometry>
    </collision>
  </link>
  <link name="lower_arm_link">
    <inertial>
      <origin rpy="0 0 0" xyz="0.07682091336987437 0.019449401609962638 0.0007855350559450025"/>
      <mass value="0.14931353567203562"/>
      <inertia ixx="5.3e-05" ixy="-2e-06" ixz="-7e-06" iyy="0.000234" iyz="0.0" izz="0.000268"/>
    </inertial>
    <visual>
      <origin rpy="0 0 0" xyz="-0.085177 0.018353 -0.23085"/>
      <geometry>
        <mesh filename="meshes/lower_arm_link_1.stl" scale="0.001 0.001 0.001"/>
      </geometry>
      <material name="silver"/>
    </visual>
    <collision>
      <origin rpy="0 0 0" xyz="-0.085177 0.018353 -0.23085"/>
      <geometry>
        <mesh filename="meshes/lower_arm_link_1.stl" scale="0.001 0.001 0.001"/>
      </geometry>
    </collision>
  </link>
  <link name="shoulder_link">
    <inertial>
      <origin rpy="0 0 0" xyz="0.031250252793449916 -0.0002581461462100498 0.008420217667021515"/>
      <mass value="0.12340393098325005"/>
      <inertia ixx="0.000124" ixy="-0.0" ixz="-5e-06" iyy="0.000125" iyz="1e-06" izz="3.4e-05"/>
    </inertial>
    <visual>
      <origin rpy="0 0 0" xyz="-0.025192 -0.000209 -0.066415"/>
      <geometry>
        <mesh filename="meshes/shoulder_link_1.stl" scale="0.001 0.001 0.001"/>
      </geometry>
      <material name="silver"/>
    </visual>
    <collision>
      <origin rpy="0 0 0" xyz="-0.025192 -0.000209 -0.066415"/>
      <geometry>
        <mesh filename="meshes/shoulder_link_1.stl" scale="0.001 0.001 0.001"/>
      </geometry>
    </collision>
  </link>
  <link name="upper_arm_link">
    <inertial>
      <origin rpy="0 0 0" xyz="0.0036368866597614596 0.019750801968105986 0.07224195667057687"/>
      <mass value="0.16051385984690403"/>
      <inertia ixx="0.000276" ixy="0.0" ixz="-2.3e-05" iyy="0.000244" iyz="1e-06" izz="7.1e-05"/>
    </inertial>
    <visual>
      <origin rpy="0 0 0" xyz="-0.0565 0.01955 -0.118391"/>
      <geometry>
        <mesh filename="meshes/upper_arm_link_1.stl" scale="0.001 0.001 0.001"/>
      </geometry>
      <material name="silver"/>
    </visual>
    <collision>
      <origin rpy="0 0 0" xyz="-0.0565 0.01955 -0.118391"/>
      <geometry>
        <mesh filename="meshes/upper_arm_link_1.stl" scale="0.001 0.001 0.001"/>
      </geometry>
    </collision>
  </link>
  <link name="left_jaw">
    <inertial>
      <origin rpy="0 0 0" xyz="0.023806479253455026 -0.0016996718789872856 -0.019446683209120547"/>
      <mass value="0.016624081834698816"/>
      <inertia ixx="4e-06" ixy="-0.0" ixz="1e-06" iyy="8e-06" iyz="0.0" izz="6e-06"/>
    </inertial>
    <visual>
      <origin rpy="0 0 0" xyz="-0.347749 -0.040991 -0.254594"/>
      <geometry>
        <mesh filename="meshes/left_jaw_v1_1.stl" scale="0.001 0.001 0.001"/>
      </geometry>
      <material name="silver"/>
    </visual>
    <collision>
      <origin rpy="0 0 0" xyz="-0.347749 -0.040991 -0.254594"/>
      <geometry>
        <mesh filename="meshes/left_jaw_v1_1.stl" scale="0.001 0.001 0.001"/>
      </geometry>
    </collision>
  </link>
  <link name="right_jaw">
    <inertial>
      <origin rpy="0 0 0" xyz="0.023808169064152396 0.0016409164921040156 -0.02262577329786908"/>
      <mass value="0.016623969125743532"/>
      <inertia ixx="4e-06" ixy="0.0" ixz="-0.0" iyy="8e-06" iyz="0.0" izz="6e-06"/>
    </inertial>
    <visual>
      <origin rpy="0 0 0" xyz="-0.34739 -0.000594 -0.254245"/>
      <geometry>
        <mesh filename="meshes/right_jaw_v1_1.stl" scale="0.001 0.001 0.001"/>
      </geometry>
      <material name="silver"/>
    </visual>
    <collision>
      <origin rpy="0 0 0" xyz="-0.34739 -0.000594 -0.254245"/>
      <geometry>
        <mesh filename="meshes/right_jaw_v1_1.stl" scale="0.001 0.001 0.001"/>
      </geometry>
    </collision>
  </link>
  <joint name="Revolute_1" type="revolute">
    <origin rpy="0 0 0" xyz="0.025192 0.000209 0.066415"/>
    <parent link="base_link"/>
    <child link="shoulder_link"/>
    <axis xyz="0.008727 -0.0 0.999962"/>
    <!-- Calibrated 2026-04-08: measured -121.1° to 117.9°, with 3° safety margin -->
    <limit lower="-2.06" upper="2.01" effort="3.35" velocity="2.0"/>
    <dynamics damping="0.6" friction="0.052"/>
  </joint>
  <joint name="Revolute_2" type="revolute">
    <origin rpy="0 0 0" xyz="0.031308 -0.019759 0.051976"/>
    <parent link="shoulder_link"/>
    <child link="upper_arm_link"/>
    <axis xyz="-0.008726 0.999962 7.6e-05"/>
    <limit lower="-1.75" upper="1.75" effort="3.35" velocity="2.0"/>
    <dynamics damping="0.6" friction="0.052"/>
  </joint>
  <joint name="Revolute_3" type="revolute">
    <origin rpy="0 0 0" xyz="0.028677 0.001197 0.112459"/>
    <parent link="upper_arm_link"/>
    <child link="lower_arm_link"/>
    <axis xyz="-0.0 -1.0 0.0"/>
    <limit effort="3.35" lower="-1.52" upper="1.76" velocity="2.0"/>
    <dynamics damping="0.6" friction="0.052"/>
  </joint>
  <joint name="Revolute_4" type="revolute">
    <origin rpy="0 0 0" xyz="0.134099 0.000648 0.003829"/>
    <parent link="lower_arm_link"/>
    <child link="wrist_pitch_link"/>
    <axis xyz="-0.008802 -0.999924 -0.00865"/>
    <limit effort="3.35" lower="-1.69" upper="1.38" velocity="2.0"/>
    <dynamics damping="0.6" friction="0.052"/>
  </joint>
  <joint name="Revolute_5" type="revolute">
    <origin rpy="0 0 0" xyz="0.029296 0.019056 0.036617"/>
    <parent link="wrist_pitch_link"/>
    <child link="wrist_yaw_link"/>
    <axis xyz="0.014193 -5e-05 0.999899"/>
    <limit effort="3.35" lower="-1.40" upper="1.32" velocity="2.0"/>
    <dynamics damping="0.6" friction="0.052"/>
  </joint>
  <joint name="Revolute_6" type="revolute">
    <origin rpy="0 0 0" xyz="0.055567 -0.000176 -0.037221"/>
    <parent link="wrist_yaw_link"/>
    <child link="wrist_roll_link"/>
    <axis xyz="0.999922 -0.008805 -0.008802"/>
    <limit effort="3.35" lower="-3.08" upper="3.09" velocity="2.0"/>
    <dynamics damping="0.6" friction="0.052"/>
  </joint>
  <joint name="left_jaw_slider" type="prismatic">
    <origin rpy="0 0 0" xyz="0.04361 0.021616 0.020519"/>
    <parent link="wrist_roll_link"/>
    <child link="left_jaw"/>
    <axis xyz="0.008881 0.999923 0.008649"/>
    <limit effort="100" lower="-0.013" upper="0.013" velocity="100"/>
  </joint>
  <joint name="right_jaw_slider" type="prismatic">
    <origin rpy="0 0 0" xyz="0.043251 -0.022781 0.02017"/>
    <parent link="wrist_roll_link"/>
    <child link="right_jaw"/>
    <axis xyz="0.008881 0.999923 0.008649"/>
    <limit effort="100" lower="-0.013" upper="0.013" velocity="100"/>
    <mimic joint="left_jaw_slider" multiplier="-1" offset="0"/>
  </joint>
</robot>
